<?xml version="1.0" ?>
<!-- =================================================================================== -->
<!-- |    This document was autogenerated by xacro from grappler.urdf.xacro            | -->
<!-- |    EDITING THIS FILE BY HAND IS NOT RECOMMENDED                                 | -->
<!-- =================================================================================== -->
<robot name="robotino">
  <!-- Include files -->
  <material name="white">
    <color rgba="0.87 0.90 0.87 1.0"/>
  </material>
  <material name="black">
    <color rgba="0.0 0.0 0.0 1.0"/>
  </material>
  <link name="base_link">
    <inertial>
      <mass value="20"/>
      <origin xyz="0 0 0"/>
      <inertia ixx="1.0" ixy="0.0" ixz="0.0" iyy="1.0" iyz="0.0" izz="1.0"/>
    </inertial>
    <visual>
      <origin rpy="0 0 1.570795" xyz="0.01 0 0"/>
      <geometry>
        <mesh filename="package://robotino_description/meshes/RobotinoBody.dae" scale="0.01 0.01 0.01"/>
      </geometry>
    </visual>
    <collision>
      <origin rpy="0 0 0" xyz="0 0 0.025"/>
      <geometry>
        <cylinder length="0.05" radius="0.18"/>
      </geometry>
    </collision>
  </link>
  <joint name="command_bridge_joint" type="fixed">
    <origin rpy="0 0 1.570795" xyz="-0.05 0 0.13"/>
    <parent link="base_link"/>
    <child link="command_bridge_link"/>
  </joint>
  <link name="command_bridge_link">
    <inertial>
      <mass value="0.00001"/>
      <origin xyz="0 0 0"/>
      <inertia ixx="1.0" ixy="0.0" ixz="0.0" iyy="1.0" iyz="0.0" izz="1.0"/>
    </inertial>
    <collision>
      <origin rpy="0 0 0" xyz="0 0 0"/>
      <geometry>
        <box size="0.25 0.11 0.16"/>
      </geometry>
    </collision>
  </link>
  <joint name="anglebracketusb_joint" type="fixed">
    <origin rpy="0 0 1.570795" xyz="0.008 0 0.137"/>
    <parent link="base_link"/>
    <child link="anglebracketusb_link"/>
  </joint>
  <link name="anglebracketusb_link">
    <inertial>
      <mass value="0.00001"/>
      <origin xyz="0 0 0"/>
      <inertia ixx="1.0" ixy="0.0" ixz="0.0" iyy="1.0" iyz="0.0" izz="1.0"/>
    </inertial>
    <visual>
      <origin rpy="0 0 0" xyz="0 0 0"/>
      <geometry>
        <mesh filename="package://robotino_description/meshes/AngleBracketUSBHub.dae" scale="0.01 0.01 0.01"/>
      </geometry>
    </visual>
  </link>
  <joint name="laser_joint" type="fixed">
    <origin rpy="0 0 1.570795" xyz="-0.022 0 0.232"/>
    <parent link="base_link"/>
    <child link="laser_link"/>
  </joint>
  <link name="laser_link">
    <inertial>
      <mass value="0.00001"/>
      <origin xyz="0 0 0"/>
      <inertia ixx="1.0" ixy="0.0" ixz="0.0" iyy="1.0" iyz="0.0" izz="1.0"/>
    </inertial>
    <visual>
      <origin rpy="0 0 1.570795" xyz="0 0 0"/>
      <geometry>
        <mesh filename="package://robotino_description/meshes/RobotinoLaserScanner.dae" scale="0.01 0.01 0.01"/>
      </geometry>
    </visual>
    <collision>
      <origin rpy="0 0 0" xyz="0 0 0.035"/>
      <geometry>
        <cylinder length="0.07" radius="0.02"/>
      </geometry>
    </collision>
  </link>
  <!--laser name="laser" parent="base_link" color="black"-->
  <!--origin xyz="-0.02 0 0.2"/-->
  <!--/laser-->
  <!--kinect name="kinect" parent="base_link" color="black" vlimit="1.571" llimit="-0.47" ulimit="0.47"-->
  <!--origin xyz="-0.02 0 0.2"/-->
  <!--/kinect-->
  <link name="grappler_base_link"/>
  <joint name="grappler_base_joint" type="fixed">
    <origin xyz="0 0 0"/>
    <parent link="base_link"/>
    <child link="grappler_base_link"/>
  </joint>
  <link name="grappler_shoulder_pan_link"/>
  <joint name="grappler_shoulder_pan_joint" type="continuous">
    <origin rpy="0 0 0" xyz="0 0 0.105"/>
    <axis xyz="0 0 1"/>
    <parent link="grappler_base_link"/>
    <child link="grappler_shoulder_pan_link"/>
  </joint>
  <joint name="grappler_shoulder_tilt_joint" type="fixed">
    <origin xyz="0.07 0 0"/>
    <parent link="grappler_shoulder_pan_link"/>
    <child link="grappler_shoulder_tilt_link"/>
  </joint>
  <link name="grappler_shoulder_tilt_link">
    <inertial>
      <mass value="0.00001"/>
      <origin xyz="0 0 0"/>
      <inertia ixx="1.0" ixy="0.0" ixz="0.0" iyy="1.0" iyz="0.0" izz="1.0"/>
    </inertial>
    <visual>
      <origin rpy="0 0 0" xyz="0 0 0"/>
      <geometry>
        <box size="0.039 0.04 0.06"/>
      </geometry>
      <material name="black"/>
    </visual>
    <collision>
      <origin rpy="0 0 0" xyz="0 0 0"/>
      <geometry>
        <box size="0.039 0.04 0.06"/>
      </geometry>
    </collision>
  </link>
  <joint name="grappler_arm_joint" type="revolute">
    <origin rpy="0 0 0" xyz="0 0 0.0165"/>
    <axis xyz="0 1 0"/>
    <limit effort="30" lower="-2.617" upper="2.617" velocity="1.571"/>
    <parent link="grappler_shoulder_tilt_link"/>
    <child link="grappler_arm_link"/>
  </joint>
  <link name="grappler_arm_link">
    <inertial>
      <mass value="0.00001"/>
      <origin xyz="0 0 0.07"/>
      <inertia ixx="1.0" ixy="0.0" ixz="0.0" iyy="1.0" iyz="0.0" izz="1.0"/>
    </inertial>
    <visual>
      <!--origin xyz="0 0 0" rpy="0 0 0" /-->
      <origin xyz="0 0 0.07"/>
      <geometry>
        <box size="0.034 0.049 0.14"/>
      </geometry>
      <material name="white"/>
    </visual>
    <collision>
      <origin xyz="0 0 0.07"/>
      <geometry>
        <box size="0.034 0.049 0.14"/>
      </geometry>
    </collision>
  </link>
  <joint name="grappler_forearm_joint" type="revolute">
    <origin rpy="0 0 0" xyz="0 0 0.14"/>
    <axis xyz="0 1 0"/>
    <limit effort="30" lower="-2.617" upper="2.617" velocity="1.571"/>
    <parent link="grappler_arm_link"/>
    <child link="grappler_forearm_link"/>
  </joint>
  <link name="grappler_forearm_link">
    <inertial>
      <mass value="0.00001"/>
      <origin xyz="0 0 0.0505"/>
      <inertia ixx="1.0" ixy="0.0" ixz="0.0" iyy="1.0" iyz="0.0" izz="1.0"/>
    </inertial>
    <visual>
      <!--origin xyz="0 0 0" rpy="0 0 0" /-->
      <origin xyz="0 0 0.0505"/>
      <geometry>
        <box size="0.035 0.035 0.101"/>
      </geometry>
      <material name="black"/>
    </visual>
    <collision>
      <origin xyz="0 0 0.0505"/>
      <geometry>
        <box size="0.035 0.035 0.101"/>
      </geometry>
    </collision>
  </link>
  <joint name="grappler_wrist_joint" type="revolute">
    <origin rpy="0 0 0" xyz="0 0 0.078"/>
    <axis xyz="0 1 0"/>
    <limit effort="30" lower="-2.617" upper="2.617" velocity="1.571"/>
    <parent link="grappler_forearm_link"/>
    <child link="grappler_wrist_link"/>
  </joint>
  <link name="grappler_wrist_link">
    <inertial>
      <mass value="0.00001"/>
      <origin xyz="0 0 0.0355"/>
      <inertia ixx="1.0" ixy="0.0" ixz="0.0" iyy="1.0" iyz="0.0" izz="1.0"/>
    </inertial>
    <visual>
      <!--origin xyz="0 0 0" rpy="0 0 0" /-->
      <origin xyz="0 0 0.0355"/>
      <geometry>
        <box size="0.046 0.05 0.071"/>
      </geometry>
      <material name="white"/>
    </visual>
    <collision>
      <origin xyz="0 0 0.0355"/>
      <geometry>
        <box size="0.046 0.05 0.071"/>
      </geometry>
    </collision>
  </link>
  <joint name="grappler_finger01_joint" type="prismatic">
    <origin rpy="0 0 0" xyz="0.015 0.0215 0.071"/>
    <axis xyz="0 1 0"/>
    <limit effort="30" lower="0.0" upper="0.015" velocity="1.571"/>
    <parent link="grappler_wrist_link"/>
    <child link="grappler_finger01_link"/>
  </joint>
  <link name="grappler_finger01_link">
    <inertial>
      <mass value="0.00001"/>
      <origin xyz="0 0 0.01"/>
      <inertia ixx="1.0" ixy="0.0" ixz="0.0" iyy="1.0" iyz="0.0" izz="1.0"/>
    </inertial>
    <visual>
      <origin rpy="0 0 0" xyz="0 0 0.01"/>
      <geometry>
        <box size="0.046 0.007 0.02"/>
      </geometry>
      <material name="black"/>
    </visual>
    <collision>
      <origin rpy="0 0 0" xyz="0 0 0.01"/>
      <geometry>
        <box size="0.046 0.007 0.02"/>
      </geometry>
    </collision>
  </link>
  <joint name="grappler_finger02_joint" type="prismatic">
    <origin rpy="0 0 0" xyz="0.015 -0.0215 0.071"/>
    <axis xyz="0 1 0"/>
    <limit effort="30" lower="-0.015" upper="0.0" velocity="1.571"/>
    <parent link="grappler_wrist_link"/>
    <child link="grappler_finger02_link"/>
  </joint>
  <link name="grappler_finger02_link">
    <inertial>
      <mass value="0.00001"/>
      <origin xyz="0 0 0.01"/>
      <inertia ixx="1.0" ixy="0.0" ixz="0.0" iyy="1.0" iyz="0.0" izz="1.0"/>
    </inertial>
    <visual>
      <origin rpy="3.14159 0 0" xyz="0 0 0.01"/>
      <geometry>
        <box size="0.046 0.007 0.02"/>
      </geometry>
      <material name="black"/>
    </visual>
    <collision>
      <origin rpy="0 0 0" xyz="0 0 0.01"/>
      <geometry>
        <box size="0.046 0.007 0.02"/>
      </geometry>
    </collision>
  </link>
</robot>

